Traceback (most recent call last):
  File "/home/codespace/.cache/pypoetry/virtualenvs/semiconductor-stock-analysis-xIsz-ESt-py3.12/lib/python3.12/site-packages/jupyter_core/utils/__init__.py", line 154, in wrapped
    asyncio.get_running_loop()
RuntimeError: no running event loop

During handling of the above exception, another exception occurred:

Traceback (most recent call last):
  File "/home/codespace/.cache/pypoetry/virtualenvs/semiconductor-stock-analysis-xIsz-ESt-py3.12/lib/python3.12/site-packages/jupyter_cache/executors/utils.py", line 58, in single_nb_execution
    executenb(
  File "/home/codespace/.cache/pypoetry/virtualenvs/semiconductor-stock-analysis-xIsz-ESt-py3.12/lib/python3.12/site-packages/nbclient/client.py", line 1319, in execute
    return NotebookClient(nb=nb, resources=resources, km=km, **kwargs).execute()
           ^^^^^^^^^^^^^^^^^^^^^^^^^^^^^^^^^^^^^^^^^^^^^^^^^^^^^^^^^^^^^^^^^^^^^
  File "/home/codespace/.cache/pypoetry/virtualenvs/semiconductor-stock-analysis-xIsz-ESt-py3.12/lib/python3.12/site-packages/jupyter_core/utils/__init__.py", line 158, in wrapped
    return loop.run_until_complete(inner)
           ^^^^^^^^^^^^^^^^^^^^^^^^^^^^^^
  File "/usr/local/python/3.12.1/lib/python3.12/asyncio/base_events.py", line 684, in run_until_complete
    return future.result()
           ^^^^^^^^^^^^^^^
  File "/home/codespace/.cache/pypoetry/virtualenvs/semiconductor-stock-analysis-xIsz-ESt-py3.12/lib/python3.12/site-packages/nbclient/client.py", line 709, in async_execute
    await self.async_execute_cell(
  File "/home/codespace/.cache/pypoetry/virtualenvs/semiconductor-stock-analysis-xIsz-ESt-py3.12/lib/python3.12/site-packages/nbclient/client.py", line 1062, in async_execute_cell
    await self._check_raise_for_error(cell, cell_index, exec_reply)
  File "/home/codespace/.cache/pypoetry/virtualenvs/semiconductor-stock-analysis-xIsz-ESt-py3.12/lib/python3.12/site-packages/nbclient/client.py", line 918, in _check_raise_for_error
    raise CellExecutionError.from_cell_and_msg(cell, exec_reply_content)
nbclient.exceptions.CellExecutionError: An error occurred while executing the following cell:
------------------
import yfinance as yf
import pandas as pd


# List of semiconductor stock tickers
tickers = ['NVDA', 'INTC', 'AMD', 'QCOM', 'TSM']

# Set the time period for historical data (adjust as needed)
start_date = '2015-01-01'
end_date = '2023-12-31'

# Dictionary to hold data for each stock
stock_data = {}

# Fetch data for each stock
for ticker in tickers:
    print("Fetching data for {}...".format(ticker))
    stock_data[ticker] = yf.download(ticker, start=start_date, end=end_date)

# Combine data into a single DataFrame
# Using adjusted close prices and aligning by date
combined_data = pd.concat([stock_data[ticker]['Adj Close'].rename(ticker) for ticker in tickers], axis=1)

# Save to CSV
combined_data.to_csv('semiconductor_stock_data.csv')

print("Data fetched and saved to 'semiconductor_stock_data.csv'")
------------------


[31m---------------------------------------------------------------------------[39m
[31mModuleNotFoundError[39m                       Traceback (most recent call last)
[36mCell[39m[36m [39m[32mIn[1][39m[32m, line 1[39m
[32m----> [39m[32m1[39m [38;5;28;01mimport[39;00m[38;5;250m [39m[34;01myfinance[39;00m[38;5;250m [39m[38;5;28;01mas[39;00m[38;5;250m [39m[34;01myf[39;00m
[32m      2[39m [38;5;28;01mimport[39;00m[38;5;250m [39m[34;01mpandas[39;00m[38;5;250m [39m[38;5;28;01mas[39;00m[38;5;250m [39m[34;01mpd[39;00m
[32m      5[39m [38;5;66;03m# List of semiconductor stock tickers[39;00m

[31mModuleNotFoundError[39m: No module named 'yfinance'

